<robot name="arm">
	<link name="base_link"/>
	
	<joint name="joint_0" type="fixed">
		<parent link="base_link"/>
		<child link="link_0"/>
	</joint>
	
	<link name="link_0">
		<visual>
			<geometry>
				<cylinder length="0.1" radius="0.05"/>
			</geometry>
			<origin xyz="0 0.0 0.05" rpy="0 0 0"/>
			<material name="red">
				<color rgba="1.0 0.0 0.0 1.0"/>
			</material>
		</visual>
	</link>
	


	<joint name="joint_1" type="revolute">
		<parent link="link_0"/>
		<child link="link_1"/>
		<origin xyz="0.0 0.0 0.1" rpy="0 0 0"/>
		<limit lower="-4.0" upper="4.0" effort="0" velocity="0"/>
		<axis xyz="0 1 0"/>
	</joint>

	<link name="link_1">
		<visual>
			<geometry>
				<cylinder length="0.2" radius="0.05"/>
			</geometry>
			<origin xyz="0 0.0 0.1" rpy="0 0 0"/>
			<material name="red"/>
		</visual>
	</link>



	<joint name="joint_2" type="revolute">
		<parent link="link_1"/>
		<child link="link_2"/>
		<origin xyz="0.0 0.0 0.2" rpy="0 0 0"/>
		<limit lower="-4.0" upper="4.0" effort="0" velocity="0"/>
		<axis xyz="0 0 1"/>
	</joint>

	<link name="link_2">
		<visual>
			<geometry>
				<box size="0.1 0.1 0.1"/>
			</geometry>
			<origin xyz="0 0.0 0.05" rpy="0 0 0"/>
			<material name="blue">
				<color rgba="0.0 0.0 1.0 1.0"/>
			</material>
		</visual>
	</link>



	<joint name="joint_3" type="revolute">
		<parent link="link_2"/>
		<child link="link_3"/>
		<origin xyz="0.0 0.0 0.1" rpy="0 0 0"/>
		<limit lower="-4.0" upper="4.0" effort="0" velocity="0"/>
		<axis xyz="0 1 0"/>
	</joint>

	<link name="link_3">
		<visual>
			<geometry>
				<cylinder length="0.15" radius="0.05"/>
			</geometry>
			<origin xyz="0 0.0 0.075" rpy="0 0 0"/>
			<material name="red"/>
		</visual>
	</link>



	<joint name="joint_4" type="revolute">
		<parent link="link_3"/>
		<child link="link_4"/>
		<origin xyz="0.0 0.0 0.15" rpy="0 0 0"/>
		<limit lower="-4.0" upper="4.0" effort="0" velocity="0"/>
		<axis xyz="0 0 1"/>
	</joint>

	<link name="link_4">
		<visual>
			<geometry>
				<box size="0.1 0.1 0.1"/>
			</geometry>
			<origin xyz="0 0.0 0.05" rpy="0 0 0"/>
			<material name="blue"/>
		</visual>
	</link>



	<joint name="joint_5" type="revolute">
		<parent link="link_4"/>
		<child link="link_5"/>
		<origin xyz="0.0 0.0 0.1" rpy="0 0 0"/>
		<limit lower="-4.0" upper="4.0" effort="0" velocity="0"/>
		<axis xyz="0 1 0"/>
	</joint>

	<link name="link_5">
		<visual>
			<geometry>
				<cylinder length="0.05" radius="0.025"/>
			</geometry>
			<origin xyz="0 0.0 0.025" rpy="0 0 0"/>
			<material name="red"/>
		</visual>
	</link>



	<joint name="joint_6" type="revolute">
		<parent link="link_5"/>
		<child link="link_6"/>
		<origin xyz="0.0 0.0 0.0" rpy="0 0 0"/>
		<limit lower="-4.0" upper="4.0" effort="0" velocity="0"/>
		<axis xyz="1 0 0"/>
	</joint>

	<link name="link_6">
		<visual>
			<geometry>
				<box size="0.12 0.07 0.15"/>
			</geometry>
			<origin xyz="0.0 0.0 0.075" rpy="0 0 0"/>
			<material name="yellow">
				<color rgba="1.0 1.0 0.0 1.0"/>
			</material>
		</visual>
	</link>
</robot>
